Workbook

Sheet Raw Data
A1: District | B1: Province | C1: Year | D1: Mean Rainfall (mm) | E1: Total Rainfall (mm) | F1: Max Daily (mm) | G1: Min Daily (mm) | H1: Std Dev (mm) | I1: CV (%) | J1: Avg Rainy Days | K1: District Area (km²) | L1: 11-Yr Mean (mm) | M1: Anomaly (mm) | N1: Flood Area (km²) | O1: Flood % of District Area
A2: Abbottabad | B2: Khyber Pakhtunkhwa | C2: 2015 | D2: 832.91663 | E2: 13303.802 | F2: 1086.2699 | G2: 620.04076 | H2: 115.801 | I2: 13.903072 | J2: 32.635895 | K2: 1639.9538 | L2: 840.03595 | M2: -7.1193186 | N2: 0.15782055 | O2: 0.0096234755
A3: Abbottabad | B3: Khyber Pakhtunkhwa | C3: 2016 | D3: 727.64711 | E3: 11622.379 | F3: 991.28638 | G3: 521.69593 | H3: 114.66612 | I3: 15.758479 | J3: 29.373435 | K3: 1639.9538 | L3: 840.03595 | M3: -112.38884 | N3: 0.57436198 | O3: 0.035023058
A4: Abbottabad | B4: Khyber Pakhtunkhwa | C4: 2017 | D4: 672.50932 | E4: 10741.688 | F4: 888.32466 | G4: 510.01031 | H4: 92.592092 | I4: 13.76815 | J4: 34.604959 | K4: 1639.9538 | L4: 840.03595 | M4: -167.52663 | N4: 0.046108374 | O4: 0.0028115654
A5: Abbottabad | B5: Khyber Pakhtunkhwa | C5: 2018 | D5: 844.82758 | E5: 13494.05 | F5: 1083.8031 | G5: 651.66969 | H5: 98.511133 | I5: 11.660501 | J5: 35.367542 | K5: 1639.9538 | L5: 840.03595 | M5: 4.791632 | N5: 0.062246554 | O5: 0.0037956285
A6: Abbottabad | B6: Khyber Pakhtunkhwa | C6: 2019 | D6: 788.81586 | E6: 12599.4 | F6: 1040.0534 | G6: 575.55482 | H6: 113.29084 | I6: 14.36214 | J6: 26.1726 | K6: 1639.9538 | L6: 840.03595 | M6: -51.220096 | N6: 0.038885938 | O6: 0.0023711605
A7: Abbottabad | B7: Khyber Pakhtunkhwa | C7: 2020 | D7: 785.44602 | E7: 12545.575 | F7: 1029.9209 | G7: 609.5445 | H7: 111.44488 | I7: 14.188738 | J7: 31.195924 | K7: 1639.9538 | L7: 840.03595 | M7: -54.589933 | N7: 0.044669572 | O7: 0.0027238311
A8: Abbottabad | B8: Khyber Pakhtunkhwa | C8: 2021 | D8: 951.73766 | E8: 15201.676 | F8: 1330.9329 | G8: 660.28582 | H8: 166.37376 | I8: 17.481052 | J8: 19.293641 | K8: 1639.9538 | L8: 840.03595 | M8: 111.70171 | N8: 0.04909695 | O8: 0.0029938008
A9: Abbottabad | B9: Khyber Pakhtunkhwa | C9: 2022 | D9: 808.08524 | E9: 12907.181 | F9: 1084.4258 | G9: 602.87927 | H9: 113.44914 | I9: 14.039254 | J9: 28.830592 | K9: 1639.9538 | L9: 840.03595 | M9: -31.950709 | N9: 0.054882005 | O9: 0.0033465579
A10: Abbottabad | B10: Khyber Pakhtunkhwa | C10: 2023 | D10: 933.90653 | E10: 14916.868 | F10: 1232.98 | G10: 681.50271 | H10: 141.01358 | I10: 15.099325 | J10: 22.960717 | K10: 1639.9538 | L10: 840.03595 | M10: 93.870574 | N10: 0.069423748 | O10: 0.0042332746
A11: Abbottabad | B11: Khyber Pakhtunkhwa | C11: 2024 | D11: 807.12525 | E11: 12891.848 | F11: 1040.7886 | G11: 613.08627 | H11: 101.95909 | I11: 12.632375 | J11: 35.253621 | K11: 1639.9538 | L11: 840.03595 | M11: -32.910705 | N11: 0.027078922 | O11: 0.0016512003
A12: Abbottabad | B12: Khyber Pakhtunkhwa | C12: 2025 | D12: 1087.3783 | E12: 17368.203 | F12: 1486.8223 | G12: 799.08714 | H12: 173.47438 | I12: 15.953453 | J12: 46.084704 | K12: 1639.9538 | L12: 840.03595 | M12: 247.34232 | N12: 0.047315981 | O12: 0.002885202
A13: Astore | B13: Gilgit Baltistan | C13: 2015 | D13: 232.11894 | E13: 11777.078 | F13: 825.12411 | G13: 68.795418 | H13: 174.85066 | I13: 75.328043 | J13: 19.709924 | K13: 5132.6571 | L13: 197.04586 | M13: 35.073085 | N13: 1.5033443 | O13: 0.029289786
... A1761: Ziarat | B1761: Balochistan | C1761: 2025 | D1761: 105.09049 | E1761: 3209.9994 | F1761: 191.67235 | G1761: 43.703607 | H1761: 35.558117 | I1761: 33.835713 | J1761: 14.902555 | K1761: 3274.7544 | L1761: 96.307141 | M1761: 8.7833513 | N1761: 0.11908639 | O1761: 0.0036364983

Sheet Classification
A1: District | B1: Province | C1: Year | D1: Anomaly (mm) | E1: Anomaly (% of 11-Yr Mean) | F1: Rainfall Classification | G1: CV (%) | H1: Variability Classification | I1: Flood % of District Area | J1: Flood Severity
A2: ='Raw Data'!A2 | B2: ='Raw Data'!B2 | C2: ='Raw Data'!C2 | D2: ='Raw Data'!M2 | E2: ='Raw Data'!M2/'Raw Data'!L2*100 | F2: =IF(E2>15,"Wet Year",IF(E2<-15,"Dry Year","Normal Year")) | G2: ='Raw Data'!I2 | H2: =IF(G2<15,"Low Variability",IF(G2<=35,"Moderate Variability","High Variability")) | I2: ='Raw Data'!O2 | J2: =IF(I2=0,"No Flood",IF(I2<=0.5,"Low",IF(I2<=2,"Moderate","High")))
A3: ='Raw Data'!A3 | B3: ='Raw Data'!B3 | C3: ='Raw Data'!C3 | D3: ='Raw Data'!M3 | E3: ='Raw Data'!M3/'Raw Data'!L3*100 | F3: =IF(E3>15,"Wet Year",IF(E3<-15,"Dry Year","Normal Year")) | G3: ='Raw Data'!I3 | H3: =IF(G3<15,"Low Variability",IF(G3<=35,"Moderate Variability","High Variability")) | I3: ='Raw Data'!O3 | J3: =IF(I3=0,"No Flood",IF(I3<=0.5,"Low",IF(I3<=2,"Moderate","High")))
A4: ='Raw Data'!A4 | B4: ='Raw Data'!B4 | C4: ='Raw Data'!C4 | D4: ='Raw Data'!M4 | E4: ='Raw Data'!M4/'Raw Data'!L4*100 | F4: =IF(E4>15,"Wet Year",IF(E4<-15,"Dry Year","Normal Year")) | G4: ='Raw Data'!I4 | H4: =IF(G4<15,"Low Variability",IF(G4<=35,"Moderate Variability","High Variability")) | I4: ='Raw Data'!O4 | J4: =IF(I4=0,"No Flood",IF(I4<=0.5,"Low",IF(I4<=2,"Moderate","High")))
A5: ='Raw Data'!A5 | B5: ='Raw Data'!B5 | C5: ='Raw Data'!C5 | D5: ='Raw Data'!M5 | E5: ='Raw Data'!M5/'Raw Data'!L5*100 | F5: =IF(E5>15,"Wet Year",IF(E5<-15,"Dry Year","Normal Year")) | G5: ='Raw Data'!I5 | H5: =IF(G5<15,"Low Variability",IF(G5<=35,"Moderate Variability","High Variability")) | I5: ='Raw Data'!O5 | J5: =IF(I5=0,"No Flood",IF(I5<=0.5,"Low",IF(I5<=2,"Moderate","High")))
A6: ='Raw Data'!A6 | B6: ='Raw Data'!B6 | C6: ='Raw Data'!C6 | D6: ='Raw Data'!M6 | E6: ='Raw Data'!M6/'Raw Data'!L6*100 | F6: =IF(E6>15,"Wet Year",IF(E6<-15,"Dry Year","Normal Year")) | G6: ='Raw Data'!I6 | H6: =IF(G6<15,"Low Variability",IF(G6<=35,"Moderate Variability","High Variability")) | I6: ='Raw Data'!O6 | J6: =IF(I6=0,"No Flood",IF(I6<=0.5,"Low",IF(I6<=2,"Moderate","High")))
A7: ='Raw Data'!A7 | B7: ='Raw Data'!B7 | C7: ='Raw Data'!C7 | D7: ='Raw Data'!M7 | E7: ='Raw Data'!M7/'Raw Data'!L7*100 | F7: =IF(E7>15,"Wet Year",IF(E7<-15,"Dry Year","Normal Year")) | G7: ='Raw Data'!I7 | H7: =IF(G7<15,"Low Variability",IF(G7<=35,"Moderate Variability","High Variability")) | I7: ='Raw Data'!O7 | J7: =IF(I7=0,"No Flood",IF(I7<=0.5,"Low",IF(I7<=2,"Moderate","High")))
A8: ='Raw Data'!A8 | B8: ='Raw Data'!B8 | C8: ='Raw Data'!C8 | D8: ='Raw Data'!M8 | E8: ='Raw Data'!M8/'Raw Data'!L8*100 | F8: =IF(E8>15,"Wet Year",IF(E8<-15,"Dry Year","Normal Year")) | G8: ='Raw Data'!I8 | H8: =IF(G8<15,"Low Variability",IF(G8<=35,"Moderate Variability","High Variability")) | I8: ='Raw Data'!O8 | J8: =IF(I8=0,"No Flood",IF(I8<=0.5,"Low",IF(I8<=2,"Moderate","High")))
A9: ='Raw Data'!A9 | B9: ='Raw Data'!B9 | C9: ='Raw Data'!C9 | D9: ='Raw Data'!M9 | E9: ='Raw Data'!M9/'Raw Data'!L9*100 | F9: =IF(E9>15,"Wet Year",IF(E9<-15,"Dry Year","Normal Year")) | G9: ='Raw Data'!I9 | H9: =IF(G9<15,"Low Variability",IF(G9<=35,"Moderate Variability","High Variability")) | I9: ='Raw Data'!O9 | J9: =IF(I9=0,"No Flood",IF(I9<=0.5,"Low",IF(I9<=2,"Moderate","High")))
A10: ='Raw Data'!A10 | B10: ='Raw Data'!B10 | C10: ='Raw Data'!C10 | D10: ='Raw Data'!M10 | E10: ='Raw Data'!M10/'Raw Data'!L10*100 | F10: =IF(E10>15,"Wet Year",IF(E10<-15,"Dry Year","Normal Year")) | G10: ='Raw Data'!I10 | H10: =IF(G10<15,"Low Variability",IF(G10<=35,"Moderate Variability","High Variability")) | I10: ='Raw Data'!O10 | J10: =IF(I10=0,"No Flood",IF(I10<=0.5,"Low",IF(I10<=2,"Moderate","High")))
A11: ='Raw Data'!A11 | B11: ='Raw Data'!B11 | C11: ='Raw Data'!C11 | D11: ='Raw Data'!M11 | E11: ='Raw Data'!M11/'Raw Data'!L11*100 | F11: =IF(E11>15,"Wet Year",IF(E11<-15,"Dry Year","Normal Year")) | G11: ='Raw Data'!I11 | H11: =IF(G11<15,"Low Variability",IF(G11<=35,"Moderate Variability","High Variability")) | I11: ='Raw Data'!O11 | J11: =IF(I11=0,"No Flood",IF(I11<=0.5,"Low",IF(I11<=2,"Moderate","High")))
A12: ='Raw Data'!A12 | B12: ='Raw Data'!B12 | C12: ='Raw Data'!C12 | D12: ='Raw Data'!M12 | E12: ='Raw Data'!M12/'Raw Data'!L12*100 | F12: =IF(E12>15,"Wet Year",IF(E12<-15,"Dry Year","Normal Year")) | G12: ='Raw Data'!I12 | H12: =IF(G12<15,"Low Variability",IF(G12<=35,"Moderate Variability","High Variability")) | I12: ='Raw Data'!O12 | J12: =IF(I12=0,"No Flood",IF(I12<=0.5,"Low",IF(I12<=2,"Moderate","High")))
A13: ='Raw Data'!A13 | B13: ='Raw Data'!B13 | C13: ='Raw Data'!C13 | D13: ='Raw Data'!M13 | E13: ='Raw Data'!M13/'Raw Data'!L13*100 | F13: =IF(E13>15,"Wet Year",IF(E13<-15,"Dry Year","Normal Year")) | G13: ='Raw Data'!I13 | H13: =IF(G13<15,"Low Variability",IF(G13<=35,"Moderate Variability","High Variability")) | I13: ='Raw Data'!O13 | J13: =IF(I13=0,"No Flood",IF(I13<=0.5,"Low",IF(I13<=2,"Moderate","High")))
... A1761: ='Raw Data'!A1761 | B1761: ='Raw Data'!B1761 | C1761: ='Raw Data'!C1761 | D1761: ='Raw Data'!M1761 | E1761: ='Raw Data'!M1761/'Raw Data'!L1761*100 | F1761: =IF(E1761>15,"Wet Year",IF(E1761<-15,"Dry Year","Normal Year")) | G1761: ='Raw Data'!I1761 | H1761: =IF(G1761<15,"Low Variability",IF(G1761<=35,"Moderate Variability","High Variability")) | I1761: ='Raw Data'!O1761 | J1761: =IF(I1761=0,"No Flood",IF(I1761<=0.5,"Low",IF(I1761<=2,"Moderate","High")))

Sheet Correlation
A1: District | B1: Province | C1: Rainfall-Flood Correlation (r) | D1: Relationship Strength | E1: Interpretation Note
A2: Abbottabad | B2: Khyber Pakhtunkhwa | C2: -0.3105 | D2: Moderate Negative | E2: Negative correlation — flooding driven by upstream/glacial factors, not local rainfall
A3: Astore | B3: Gilgit Baltistan | C3: -0.0989 | D3: Weak / No Relationship
A4: Attock | B4: Punjab | C4: 0.3242 | D4: Moderate Positive
A5: Awaran | B5: Balochistan | C5: 0.7974 | D5: Strong Positive
A6: Badin | B6: Sindh | C6: 0.3618 | D6: Moderate Positive
A7: Bagh | B7: Azad Kashmir | C7: -0.1426 | D7: Weak / No Relationship
A8: Bahawalnagar | B8: Punjab | C8: 0.695 | D8: Strong Positive
A9: Bahawalpur | B9: Punjab | C9: 0.6025 | D9: Strong Positive
A10: Bajaur | B10: Khyber Pakhtunkhwa | C10: -0.0683 | D10: Weak / No Relationship
A11: Bannu | B11: Khyber Pakhtunkhwa | C11: 0.4316 | D11: Moderate Positive
A12: Barkhan | B12: Balochistan | C12: 0.4485 | D12: Moderate Positive
A13: Batagram | B13: Khyber Pakhtunkhwa | C13: 0.1008 | D13: Weak / No Relationship
A14: Bhakkar | B14: Punjab | C14: -0.016 | D14: Weak / No Relationship
... A16: Buner | B16: Khyber Pakhtunkhwa | C16: 0.264 | D16: Moderate Positive
A17: Central Karachi | B17: Sindh | C17: -0.2145 | D17: Moderate Negative | E17: Correlation not meaningful — flood detection near-zero every year, unlike other Karachi districts
A18: Chagai | B18: Balochistan | C18: 0.0963 | D18: Weak / No Relationship
A19: Chakwal | B19: Punjab | C19: -0.2643 | D19: Moderate Negative | E19: Negative correlation — flooding driven by upstream/glacial factors, not local rainfall
A20: Chaman | B20: Balochistan | C20: 0.942 | D20: Strong Positive
A21: Charsadda | B21: Khyber Pakhtunkhwa | C21: 0.0325 | D21: Weak / No Relationship
A22: Chiniot | B22: Punjab | C22: 0.6504 | D22: Strong Positive
A23: Chitral Lower | B23: Khyber Pakhtunkhwa | C23: 0.6102 | D23: Strong Positive
A24: Chitral Upper | B24: Khyber Pakhtunkhwa | C24: 0.6794 | D24: Strong Positive
A25: D. I. Khan | B25: Khyber Pakhtunkhwa | C25: 0.5717 | D25: Strong Positive
A26: Dadu | B26: Sindh | C26: 0.8081 | D26: Strong Positive
A27: Darel | B27: Gilgit Baltistan | C27: 0.3755 | D27: Moderate Positive
A28: Dera Bugti | B28: Balochistan | C28: -0.1007 | D28: Weak / No Relationship
A29: Dera Ghazi Khan | B29: Punjab | C29: 0.2457 | D29: Moderate Positive
A30: Diamir | B30: Gilgit Baltistan | C30: 0.3658 | D30: Moderate Positive
A31: Duki | B31: Balochistan | C31: 0.5284 | D31: Strong Positive
... A46: Haveli | B46: Azad Kashmir | C46: -0.1908 | D46: Weak / No Relationship
A47: Hunza | B47: Gilgit Baltistan | C47: -0.2967 | D47: Moderate Negative | E47: Negative correlation — flooding driven by upstream/glacial factors, not local rainfall
A48: Hyderabad | B48: Sindh | C48: 0.8219 | D48: Strong Positive
A49: Islamabad | B49: Islamabad | C49: 0.0447 | D49: Weak / No Relationship
A50: Jacobabad | B50: Sindh | C50: 0.8856 | D50: Strong Positive
A51: Jaffarabad | B51: Balochistan | C51: 0.8909 | D51: Strong Positive
A52: Jamshoro | B52: Sindh | C52: 0.7414 | D52: Strong Positive
A53: Jhal Magsi | B53: Balochistan | C53: 0.7569 | D53: Strong Positive
A54: Jhang | B54: Punjab | C54: 0.5805 | D54: Strong Positive
A55: Jhelum | B55: Punjab | C55: -0.0328 | D55: Weak / No Relationship
...

Sheet Trend
A1: District | B1: Province | C1: Linear 2026 (mm) | D1: Linear 2027 (mm) | E1: Linear R² | F1: Linear Slope (mm/yr) | G1: Quadratic 2026 (mm) | H1: Quadratic 2027 (mm) | I1: Trend Classification | J1: Note
A2: Abbottabad | B2: Khyber Pakhtunkhwa | C2: 974.43 | D2: 996.83 | E2: 0.4215 | F2: 22.399 | G2: 974.79 | H2: 997.34 | I2: =IF(E2>=0.5,IF(F2>0,"Strong Rising Trend","Strong Falling Trend"),IF(E2>=0.2,IF(F2>0,"Moderate Rising Trend","Moderate Falling Trend"),"Weak / Unreliable Trend")) | J2: Statistical trend only, not a meteorological forecast
A3: Astore | B3: Gilgit Baltistan | C3: 215.17 | D3: 218.2 | E3: 0.1295 | F3: 3.021 | G3: 215.24 | H3: 218.28 | I3: =IF(E3>=0.5,IF(F3>0,"Strong Rising Trend","Strong Falling Trend"),IF(E3>=0.2,IF(F3>0,"Moderate Rising Trend","Moderate Falling Trend"),"Weak / Unreliable Trend")) | J3: Statistical trend only, not a meteorological forecast
A4: Attock | B4: Punjab | C4: 495.24 | D4: 498.93 | E4: 0.064 | F4: 3.687 | G4: 495.33 | H4: 499.05 | I4: =IF(E4>=0.5,IF(F4>0,"Strong Rising Trend","Strong Falling Trend"),IF(E4>=0.2,IF(F4>0,"Moderate Rising Trend","Moderate Falling Trend"),"Weak / Unreliable Trend")) | J4: Statistical trend only, not a meteorological forecast
A5: Awaran | B5: Balochistan | C5: 162.98 | D5: 171.89 | E5: 0.1442 | F5: 8.911 | G5: 163.03 | H5: 171.99 | I5: =IF(E5>=0.5,IF(F5>0,"Strong Rising Trend","Strong Falling Trend"),IF(E5>=0.2,IF(F5>0,"Moderate Rising Trend","Moderate Falling Trend"),"Weak / Unreliable Trend")) | J5: Statistical trend only, not a meteorological forecast
A6: Badin | B6: Sindh | C6: 341.25 | D6: 355.15 | E6: 0.1797 | F6: 13.891 | G6: 341.36 | H6: 355.32 | I6: =IF(E6>=0.5,IF(F6>0,"Strong Rising Trend","Strong Falling Trend"),IF(E6>=0.2,IF(F6>0,"Moderate Rising Trend","Moderate Falling Trend"),"Weak / Unreliable Trend")) | J6: Statistical trend only, not a meteorological forecast
A7: Bagh | B7: Azad Kashmir | C7: 740.32 | D7: 754.69 | E7: 0.2124 | F7: 14.371 | G7: 740.56 | H7: 755.03 | I7: =IF(E7>=0.5,IF(F7>0,"Strong Rising Trend","Strong Falling Trend"),IF(E7>=0.2,IF(F7>0,"Moderate Rising Trend","Moderate Falling Trend"),"Weak / Unreliable Trend")) | J7: Statistical trend only, not a meteorological forecast
A8: Bahawalnagar | B8: Punjab | C8: 290.36 | D8: 302.94 | E8: 0.3786 | F8: 12.579 | G8: 290.61 | H8: 303.28 | I8: =IF(E8>=0.5,IF(F8>0,"Strong Rising Trend","Strong Falling Trend"),IF(E8>=0.2,IF(F8>0,"Moderate Rising Trend","Moderate Falling Trend"),"Weak / Unreliable Trend")) | J8: Statistical trend only, not a meteorological forecast
A9: Bahawalpur | B9: Punjab | C9: 277.61 | D9: 287.3 | E9: 0.1646 | F9: 9.692 | G9: 277.78 | H9: 287.54 | I9: =IF(E9>=0.5,IF(F9>0,"Strong Rising Trend","Strong Falling Trend"),IF(E9>=0.2,IF(F9>0,"Moderate Rising Trend","Moderate Falling Trend"),"Weak / Unreliable Trend")) | J9: Statistical trend only, not a meteorological forecast
A10: Bajaur | B10: Khyber Pakhtunkhwa | C10: 226.76 | D10: 217.4 | E10: 0.241 | F10: -9.36 | G10: 226.66 | H10: 217.24 | I10: =IF(E10>=0.5,IF(F10>0,"Strong Rising Trend","Strong Falling Trend"),IF(E10>=0.2,IF(F10>0,"Moderate Rising Trend","Moderate Falling Trend"),"Weak / Unreliable Trend")) | J10: Statistical trend only, not a meteorological forecast
A11: Bannu | B11: Khyber Pakhtunkhwa | C11: 217.38 | D11: 211.91 | E11: 0.1386 | F11: -5.467 | G11: 217.35 | H11: 211.85 | I11: =IF(E11>=0.5,IF(F11>0,"Strong Rising Trend","Strong Falling Trend"),IF(E11>=0.2,IF(F11>0,"Moderate Rising Trend","Moderate Falling Trend"),"Weak / Unreliable Trend")) | J11: Statistical trend only, not a meteorological forecast
A12: Barkhan | B12: Balochistan | C12: 316.03 | D12: 322.44 | E12: 0.0569 | F12: 6.412 | G12: 316.14 | H12: 322.59 | I12: =IF(E12>=0.5,IF(F12>0,"Strong Rising Trend","Strong Falling Trend"),IF(E12>=0.2,IF(F12>0,"Moderate Rising Trend","Moderate Falling Trend"),"Weak / Unreliable Trend")) | J12: Statistical trend only, not a meteorological forecast
A13: Batagram | B13: Khyber Pakhtunkhwa | C13: 579.07 | D13: 578.53 | E13: 0.0014 | F13: -0.545 | G13: 579.06 | H13: 578.51 | I13: =IF(E13>=0.5,IF(F13>0,"Strong Rising Trend","Strong Falling Trend"),IF(E13>=0.2,IF(F13>0,"Moderate Rising Trend","Moderate Falling Trend"),"Weak / Unreliable Trend")) | J13: Statistical trend only, not a meteorological forecast
... A161: Ziarat | B161: Balochistan | C161: 150.9 | D161: 160 | E161: 0.2566 | F161: 9.099 | G161: 151.03 | H161: 160.19 | I161: =IF(E161>=0.5,IF(F161>0,"Strong Rising Trend","Strong Falling Trend"),IF(E161>=0.2,IF(F161>0,"Moderate Rising Trend","Moderate Falling Trend"),"Weak / Unreliable Trend")) | J161: Statistical trend only, not a meteorological forecast
